[2025-01-06T09:09:09.284+0000] {taskinstance.py:1103} INFO - Dependencies all met for dep_context=non-requeueable deps ti=<TaskInstance: nba_data_pipeline.activate_telegram_bot manual__2025-01-06T09:03:10.831173+00:00 [queued]>
[2025-01-06T09:09:09.290+0000] {taskinstance.py:1103} INFO - Dependencies all met for dep_context=requeueable deps ti=<TaskInstance: nba_data_pipeline.activate_telegram_bot manual__2025-01-06T09:03:10.831173+00:00 [queued]>
[2025-01-06T09:09:09.291+0000] {taskinstance.py:1308} INFO - Starting attempt 2 of 2
[2025-01-06T09:09:09.299+0000] {taskinstance.py:1327} INFO - Executing <Task(PythonOperator): activate_telegram_bot> on 2025-01-06 09:03:10.831173+00:00
[2025-01-06T09:09:09.304+0000] {standard_task_runner.py:57} INFO - Started process 1196 to run task
[2025-01-06T09:09:09.307+0000] {standard_task_runner.py:84} INFO - Running: ['***', 'tasks', 'run', 'nba_data_pipeline', 'activate_telegram_bot', 'manual__2025-01-06T09:03:10.831173+00:00', '--job-id', '126', '--raw', '--subdir', 'DAGS_FOLDER/full_nba_data_pipeline.py', '--cfg-path', '/tmp/tmph5y47rzb']
[2025-01-06T09:09:09.313+0000] {standard_task_runner.py:85} INFO - Job 126: Subtask activate_telegram_bot
[2025-01-06T09:09:09.392+0000] {task_command.py:410} INFO - Running <TaskInstance: nba_data_pipeline.activate_telegram_bot manual__2025-01-06T09:03:10.831173+00:00 [running]> on host 1193c25bb614
[2025-01-06T09:09:09.612+0000] {taskinstance.py:1547} INFO - Exporting env vars: AIRFLOW_CTX_DAG_OWNER='***' AIRFLOW_CTX_DAG_ID='nba_data_pipeline' AIRFLOW_CTX_TASK_ID='activate_telegram_bot' AIRFLOW_CTX_EXECUTION_DATE='2025-01-06T09:03:10.831173+00:00' AIRFLOW_CTX_TRY_NUMBER='2' AIRFLOW_CTX_DAG_RUN_ID='manual__2025-01-06T09:03:10.831173+00:00'
[2025-01-06T09:09:09.613+0000] {taskinstance.py:1824} ERROR - Task failed with exception
Traceback (most recent call last):
  File "/home/airflow/.local/lib/python3.7/site-packages/airflow/operators/python.py", line 181, in execute
    return_value = self.execute_callable()
  File "/home/airflow/.local/lib/python3.7/site-packages/airflow/operators/python.py", line 198, in execute_callable
    return self.python_callable(*self.op_args, **self.op_kwargs)
  File "/opt/airflow/dags/full_nba_data_pipeline.py", line 163, in run_bot
    from bot import main
ModuleNotFoundError: No module named 'bot'
[2025-01-06T09:09:09.618+0000] {taskinstance.py:1350} INFO - Marking task as FAILED. dag_id=nba_data_pipeline, task_id=activate_telegram_bot, execution_date=20250106T090310, start_date=20250106T090909, end_date=20250106T090909
[2025-01-06T09:09:09.623+0000] {standard_task_runner.py:109} ERROR - Failed to execute job 126 for task activate_telegram_bot (No module named 'bot'; 1196)
[2025-01-06T09:09:09.641+0000] {local_task_job_runner.py:225} INFO - Task exited with return code 1
[2025-01-06T09:09:09.653+0000] {taskinstance.py:2653} INFO - 0 downstream tasks scheduled from follow-on schedule check
